Workbook

Sheet Template3
A1: Project Name: | B1: Enter your data | F1: 1.4.0.0
A2: Unit: | B2: Geniox Tera C Macro CRAH
A3: Model: | B3: TERA 170
A4: Unit summary | D4: Version 1.1.0.0
A5: Configuration | D5: TOP RETURN BOTTOM SUPPLY
A6: Cooling capacity | D6: 340.7
A7: Airflow | D7: 33333
A8: Supply/Return air temperature | D8: 14.2/44
A9: Power supply | D9: 400V-3PH-N-PE-50Hz
A10: Dimensions (W x L x H) | D10: 4082 x 1082 x 3200 mm
A11: Casing/Frame Details
A12: Panel Thickness | D12: 60 mm
A13: Panel Insulation Type / Density | D13: Rock wool 60kg/m3
A14: Panel External Sheet | D14: Z275 Steel + Polyster Painted (0,8mm)
A15: Panel Internal Sheet | D15: Z275 Steel + Polyster Painted (0,8mm)
A16: Frame Type | D16: Z275 + Epoxy Primer Polyester Painted Steel
A17: Water Cooling Coil Details
A18: Fluid | C18: WATER | E18: %
A19: Return Air Temparature | C19: 44 | E19: °C
A20: Return Air Humidity | C20: 11 | E20: %
A21: Supply Air Temparature | C21: 14.2 | E21: °C
A22: Supply Air Humidity | C22: 62.2 | E22: %
A23: Coil Pressure Drop (Air side) | C23: 102.8 | E23: Pa
A24: Coil Cooling Capacity | C24: 340.7 | E24: kW
A25: Fluid Inlet Temparature. | C25: 11 | E25: °C
A26: Fluid Outlet Temparature | C26: 22 | E26: °C
A27: Water Flow Rate | C27: 26.6 | E27: m³/h
A28: Coil Pressure Drop (Fluid side) | C28: 85.8 | E28: kPa
A29: EER (Energy Efficiency Ratio) | C29: 71
A30: Connections (Inlet-Outlet) | C30: DN 80
A31: Air density | E31: kg/m³
A32: Supply Fan Details
A33: Air Flow Rate | C33: 33333 | E33: m³/h
A34: External Pressure | C34: 111 | E34: Pa
A35: Total Static Pressure | C35: 259.3 | E35: Pa
A36: Fan Speed | C36: 1513 | E36: rpm
A37: Maximum Fan Speed | C37: 2370 | E37: rpm
A38: Total Efficiency | C38: 63 | E38: %
A39: Fan Type | C39: EC Plug Fan
A40: Voltage | C40: 3 Ph 400 | E40: V
...

Sheet Selection List
A1: CAPACITY | B1: 30 | C1: 17: 170 Kw; 23: 230 kW; 30: 300 Kw
A2: FLOW CONFIGURATION | B2: B | C2: B= TOP SIDE RETURN BOTTOM SUPPLY; F= TOP SIDE RETURN FRONT SUPPLY; M= FRONT SIDE RETURN BOTTOM SUPPLY
A3: PIPE SIDE | B3: R | C3: L=Left; R=Right
A4: WATER CONDITION | B4: L | C4: L= 20/28 ; H=20/30
A5: HUMIDIFICATION | B5: 0 | C5: S= STEAM HUMIDIFIER 15kg/h ; 0= NONE
A6: ESP | B6: H | C6: H= 100 Pa ESP; L= 50 Pa ESP ; S= …. Pa ESP
A7: DAMPER | B7: 0 | C7: 1= ON TOP ; 0= NONE
A8: Temp Sensors | B8: S | C8: S= Only Average Temp Sensor on Return/Supply Air; O= Additional Temp/Hum Sensor on Return/Supply Air
A9: Leak Detaction | B9: S | C9: S= Wire Type ; O= Additional Leak Sensor
A10: Valve Options | B10: 2 | C10: N= 0-10V Output w Temp Measurement; F= 0-10V Output w Flow/Temp Measurement; 3= 3 Way Valve; 2= 2 Way Valve w Temp Measurement; E= 2 Way Smart Energy Management Valve (EV) P= 2 Way Flow-Pressure Independent Valve (PICV)
A11: Corridor Sensor | B11: 0 | C11: 0= None; 1= Corridors dP; 2= Double dP; 3= Corridor dP, Temperature & Humidity Sensor; 4= Double Corridor dP, Temperature & Humidity Sensor; 5=Temperature & Humidity Sensor
A12: Corridor Control | B12: 0 | C12: 0: N/A; 1= Corridor Temperature Sensor is only for monitoring; 2= Corridor Temperature Sensor will be included on supply air
A13: Power Input | B13: 0 | C13: 0= 400V /3P+N / 50hZ; 1= 400V / 3P+N / 60Hz
A14: Power Option | B14: N | C14: N= None; A= ATS; B= ATS & UltraCap; U= UltraCap
A15: Power Measurment | B15: 0 | C15: 0= None; 3= Energy Analyser
A16: HMI | B16: 0 | C16: 0= None *; 1= Magnetic Text Based Display with Ethernet Socket Connection; 2= Panel Mounted Touch Panel Display
A17: Harmonic Filter | B17: 0 | C17: 0= None ; 1= Active PFC ; 2= Fans with Active PFC
A18: Panel Socket | B18: 0 | C18: 0= None; A=CF Type Socket
A19: Fire Protection | B19: N | C19: N= None; 0= Shutdown on fire without sensor; 1= Continue on fire without sensor; 2= Shutdown with Smoke; 3= Continue with Smoke
A20: Communication Protocols for BMS | B20: 0 | C20: 0=None; 1=BacNET IP; 2=BacNET MSTP; 3=Modbus RTU; 4=Modbus TCP/IP
A21: WSCO and Teamwork | B21: 0 | C21: 0= None; 1=Teamwork; 2=WSCO**; 3=Teamwork and WSCO
A22: Flow Direction | B22: F | C22: F : Supply from the front side; B : Bottom supply air to 3 sides ( front, left and right); A : All side
A23: Safety Water Control Options | B23: 1 | C23: 0= None 0 : 1= Available
A24: Unit Code = TERA C | B24: =B1&B2&B3&B4&B5&B6&B7&B8&B9&B10&B11&B12&B13&B14&B15&B16&B17&B18&B19&B20&B21&B22&B23 -> 30BRL0H0SS2000N0000N00F1 | C24: * There will be no display at all. One text-based screen can be used in all units. If you choose none, please consider that you have to buy one text-based at least. ** If there is no electrical power measurement, WSCO will not be available.
B25: =Sheet1!F218/0.6 -> 46893.437

Sheet Sheet1
A1: General Equipment | B1: Product Number | C1: Product Description | D1: Amount | E1: Unit | F1: Unit Price | G1: Total Price
A2: Labor | B2: HIZM000000010 | C2: MONTAJ İŞÇİLİK OVERHEAD | D2: =IF('Selection List'!B1=17,75.16,IF('Selection List'!B1=23,87.28,IF('Selection List'!B1=30,97.52,"VEYY"))) -> 97.52 | E2: pcs | F2: 45 | G2: =D2*F2 -> 4388.4
B3: HIZM000000041 | C3: ELEKTRİK ADAM SAAT | D3: =IF('Selection List'!B1=17,13.75,IF('Selection List'!B1=23,18.77,IF('Selection List'!B1=30,21.39,"VEYY"))) -> 21.39 | E3: pcs | F3: 15 | G3: =D3*F3 -> 320.85
B4: HIZM000000032 | C4: PANO MONTAJ İŞÇİLİK | D4: =IF('Selection List'!B1=17,19.3,IF('Selection List'!B1=23,25.83,IF('Selection List'!B1=30,27.8,"VEYY"))) -> 27.8 | E4: pcs | F4: 45 | G4: =D4*F4 -> 1251
A5: CC Coil | B5: R06TERAC00001 | C5: 80T6R2P80NC Low Temp. | D5: =IF(AND('Selection List'!B1=17,'Selection List'!B4="L"),1,0) -> 0 | E5: pcs | F5: 4043 | G5: =D5*F5 -> 0
B6: R06TERAC00002 | C6: 80T7R2P70NC High Temp. | D6: =IF(AND('Selection List'!B1=17,'Selection List'!B4="H"),1,0) -> 0 | E6: pcs | F6: 4626 | G6: =D6*F6 -> 0
B7: R06TERAC00003 | C7: 84T7R2.3P147NC Low Temp. | D7: =IF(AND('Selection List'!B1=23,'Selection List'!B4="L"),1,0) -> 0 | E7: pcs | F7: 7168 | G7: =D7*F7 -> 0
B8: R06TERAC00004 | C8: 84T8R2.3P112NC High Temp. | D8: =IF(AND('Selection List'!B1=23,'Selection List'!B4="H"),1,0) -> 0 | E8: pcs | F8: 7962 | G8: =D8*F8 -> 0
B9: R06TERAC00005 | C9: 82T7R2.3P143NC Low Temp. | D9: =IF(AND('Selection List'!B1=30,'Selection List'!B4="L"),1,0) -> 1 | E9: pcs | F9: 8572 | G9: =D9*F9 -> 8572
B10: R06TERAC00006 | C10: 82T8R2.3P112NC High Temp. | D10: =IF(AND('Selection List'!B1=30,'Selection List'!B4="H"),1,0) -> 0 | E10: pcs | F10: 9585 | G10: =D10*F10 -> 0
A11: Fan | B11: R05EBM0000284 | C11: VBH0560CTTRS / EBM / 8300100101 | D11: {=IF('Selection List'!B17=2,0,IF('Selection List'!B1=17,3,IF('Selection List'!B1=23,4,IF('Selection List'!B1=30,5,veyy))))} -> 5 | E11: pcs | F11: 812.4 | G11: =D11*F11 -> 4062
B12: R058300100546 | C12: EBM / 8300100546 | D12: =IF('Selection List'!B17=2,IF('Selection List'!B1=17,3,IF('Selection List'!B1=23,4,IF('Selection List'!B1=30,5,"0"))),0) -> 0 | E12: pcs | F12: 958 | G12: =D12*F12 -> 0
A13: Nemlendirici | B13: R13BN30150000 | C13: BUHARLI NEMLENDIRICI EL 15KG/H | D13: =IF('Selection List'!B5="S",1,0) -> 0 | E13: PCS | F13: 1231 | G13: =D13*F13 -> 0
A14: Electric Panel | B14: R140023AR0003 | C14: 1296x796x185 / Galvanized steel | D14: 1 | E14: pcs | F14: 385 | G14: =D14*F14 -> 385
A15: Air Filter | B15: R170481000727 | C15: PANEL FILTRE G4-48-1000x727 | D15: =IF(AND('Selection List'!B1=17,(OR('Selection List'!B2="F",'Selection List'!B2="B"))),6,0) -> 0 | E15: pcs | F15: 12.42 | G15: =D15*F15 -> 0
B16: R170481000672 | C16: PANEL FILTRE G4-48-1000x672 | D16: =IF(AND('Selection List'!B1=23,(OR('Selection List'!B2="F",'Selection List'!B2="B"))),8,0) -> 0 | E16: pcs | F16: 11.74 | G16: =D16*F16 -> 0
B17: R17CF41000864 | C17: 1028x864x48 G4 Panel Filtre | D17: =IF(AND('Selection List'!B1=30,(OR('Selection List'!B2="F",'Selection List'!B2="B"))),10,0) -> 10 | E17: pcs | F17: 50.68 | G17: =D17*F17 -> 506.8
B18: R170480525575 | C18: PANEL FILTRE G4-48-525x725 | D18: =IF('Selection List'!B2="M",1,0) -> 0 | E18: pcs | F18: 7.96 | G18: =D18*F18 -> 0
B19: R170480905725 | C19: PANEL FILTRE G4-48-905x725 | D19: =IF(AND('Selection List'!B2="M",'Selection List'!B1=17),4,IF(AND('Selection List'!B2="M",'Selection List'!B1=23),6,IF(AND('Selection List'!B2="M",'Selection List'!B1=30),8,0))) -> 0 | E19: pcs | F19: 11.54 | G19: =D19*F19 -> 0
A20: Casing | B20: R210090655150 | C20: Corner 66x66 Top PA6-Steel Par | D20: 4 | E20: mt | F20: 4.68 | G20: =D20*F20 -> 18.72
B21: R020090655021 | C21: Corner profile 66x66 bottom | D21: =IF('Selection List'!B1=17,7,IF('Selection List'!B1=23,8.5,IF('Selection List'!B1=30,10,"VEYY"))) -> 10 | E21: mt | F21: 10.992 | G21: =D21*F21 -> 109.92
B22: R020090655020 | C22: Corner profile 66x66 | D22: =IF('Selection List'!B1=17,19,IF('Selection List'!B1=23,20.5,IF('Selection List'!B1=30,22,"VEYY"))) -> 22 | E22: mt | F22: 10.896 | G22: =D22*F22 -> 239.712
B23: R020090653102 | C23: MULLION 50X42 ZM310AC | D23: =IF('Selection List'!B1=17,31,IF('Selection List'!B1=23,34.5,IF('Selection List'!B1=30,38,"VEYY"))) -> 38 | E23: mt | F23: 6.624 | G23: =D23*F23 -> 251.712
B24: R020090653103 | C24: 1/2 Mullion profile 25x42 ZM310AC | D24: =IF('Selection List'!B1=17,14,IF('Selection List'!B1=23,17,IF('Selection List'!B1=30,20,"VEYY"))) -> 20 | E24: mt | F24: 5.64 | G24: =D24*F24 -> 112.8
B25: R210090655073 | C25: Mullion Bracket Top/Vertical | D25: =IF('Selection List'!B1=17,4,IF('Selection List'!B1=23,6,IF('Selection List'!B1=30,8,"VEYY"))) -> 8 | E25: pcs | F25: 0.448 | G25: =D25*F25 -> 3.584
B26: R210090655065 | C26: Mullion Bracket 46,7x39,3x1,5 | D26: =IF('Selection List'!B1=17,58,IF('Selection List'!B1=23,59,IF('Selection List'!B1=30,60,"VEYY"))) -> 60 | E26: pcs | F26: 0.33 | G26: =D26*F26 -> 19.8
B27: R01B080000001 | C27: 0.80 mm Z275 DX51 RAL7035 Boyalı Rulo Sac | D27: =IF('Selection List'!B1=17,289.2,IF('Selection List'!B1=23,319.2,IF('Selection List'!B1=30,349.2,"VEYY"))) -> 349.2 | E27: kg | F27: 1.04 | G27: =D27*F27 -> 363.168
B28: R040090655040 | C28: Geniox panel profil tape/EPDM | D28: =IF('Selection List'!B1=17,89,IF('Selection List'!B1=23,97.9,IF('Selection List'!B1=30,106.8,"VEYY"))) -> 106.8 | E28: mt | F28: 2.87 | G28: =D28*F28 -> 306.516
B29: R040090655044 | C29: Door profile w/tape + 1xTPE | D29: =IF('Selection List'!B1=17,23,IF('Selection List'!B1=23,25.3,IF('Selection List'!B1=30,27.6,"VEYY"))) -> 27.6 | E29: mt | F29: 2.24 | G29: =D29*F29 -> 61.824
B30: R01GL30000275 | C30: 3.00 mm Z275 DX51 Plaka Sac | D30: =IF('Selection List'!B1=17,204,IF('Selection List'!B1=23,241,IF('Selection List'!B1=30,292,"VEYY"))) -> 292 | E30: kg | F30: 0.82 | G30: =D30*F30 -> 239.44
B31: R10YN60700002 | C31: KAYA YÜNÜ 60MM-70 KG/M3 | D31: =IF('Selection List'!B1=17,30,IF('Selection List'!B1=23,45,IF('Selection List'!B1=30,60,"VEYY"))) -> 60 | E31: m2 | F31: 4.28 | G31: =D31*F31 -> 256.8
B32: R21KT50502520 | C32: PUNTALI KAFES TELI (50mm X 50mm X2. 5mm)(1000x2000mm plakadan) | D32: =IF(AND('Selection List'!B1=30,OR('Selection List'!B2="B",'Selection List'!B2="M"),'Selection List'!B22="F"),3,IF(AND('Selection List'!B1=30,OR('Selection List'!B2="B",'Selection List'!B2="M"),'Selection List'!B22="B"),4,IF(AND('Selection List'!B1=30,OR('Selection List'!B2="B",'Selection List'!B2="M"),'Selection List'!B22="A"),6,IF(AND('Selection List'!B1=23,OR('Selection List'!B2="B",'Selection List'!B2="M"),'Selection List'!B22="F"),2,IF(AND('Selection List'!B1=23,OR('Selection List'!B2="B",'Selection List'!B2="M"),'Selection List'!B22="B"),3,IF(AND('Selection List'!B1=23,OR('Selection List'!B2="B",'Selection List'!B2="M"),'Selection List'!B22="A"),5,IF(AND('Selection List'!B1=17,OR('Selection List'!B2="B",'Selection List'!B2="M"),'Selection List'!B22="F"),2,IF(AND('Selection List'!B1=17,OR('Selection List'!B2="B",'Selection List'!B2="M"),'Selection List'!B22="B"),3,IF(AND('Selection List'!B1=17,OR('Selection List'!B2="B",'Selection List'!B2="M"),'Selection List'!B22="A"),4,"0"))))))))) -> 3 | E32: pcs | F32: 54.11 | G32: =D32*F32 -> 162.33
B33: R21KT50502530 | C33: PUNTALI KAFES TELI (50mm X 50mm X2. 5mm)(1000x3000mm plakadan) | D33: =IF(AND('Selection List'!B1=30,'Selection List'!B2="F"),5,IF(AND('Selection List'!B1=23,'Selection List'!B2="F"),4,IF(AND('Selection List'!B1=17,'Selection List'!B2="F"),3,0))) -> 0 | E33: pcs | F33: 61.7 | G33: =D33*F33 -> 0
B34: R01BY27570400 | C34: 1.2 MM 275 GR RAL7035 C.TARAF BOYALI SAC | D34: =IF('Selection List'!B1=17,18,IF('Selection List'!B1=23,54,IF('Selection List'!B1=30,90,"VEYY"))) -> 90 | E34: kg | F34: 1.05 | G34: =D34*F34 -> 94.5
B35: R01PS12000001 | C35: 1.20 mm 316 Paslanmaz Nitto 9205 Pvc Kaplamalı Rulo Sac | D35: =IF('Selection List'!B1=17,11,IF('Selection List'!B1=23,17.5,IF('Selection List'!B1=30,24,"VEYY"))) -> 24 | E35: kg | F35: 4.2 | G35: =D35*F35 -> 100.8
B36: R210090655151 | C36: Corner 25x66 Top PA6-Steel Par | D36: 4 | E36: pcs | F36: 2.82 | G36: =D36*F36 -> 11.28
B37: R210090655153 | C37: Corner 25x66 bot L PA6-Steel Par | D37: 4 | E37: pcs | F37: 2.6 | G37: =D37*F37 -> 10.4
B38: R210090655154 | C38: Corner 25x66 bot R PA6-Steel Par | D38: 2 | E38: pcs | F38: 2.6 | G38: =D38*F38 -> 5.2
B39: R19KFL8155117 | C39: 8-1551-17 Coverplate Lock Venthandle bluegrey | D39: =IF('Selection List'!B1=17,9,IF('Selection List'!B1=23,12,IF('Selection List'!B1=30,15,"VEYY"))) -> 15 | E39: pcs | F39: 1 | G39: =D39*F39 -> 15
B40: R1200000MKR40 | C40: 40'lık Makaralı Ray (L=940 mm) | D40: =IF('Selection List'!B1=17,6,IF('Selection List'!B1=23,8,IF('Selection List'!B1=30,10,"VEYY"))) -> 10 | E40: pcs | F40: 20 | G40: =D40*F40 -> 200
...

Sheet Sayfa2
B1: 17 | C1: 170
B2: 23 | C2: =230 -> 230
B3: 30 | C3: =300 -> 300
A4: FLOW CONFIGURATION | B4: B | C4: =TOP SIDE RETURN BOTTOM SUPPLY -> #NAME?
B5: F | C5: =TOP SIDE RETURN FRONT SUPPLY -> #NAME?
B6: M | C6: =FRONT SIDE RETURN BOTTOM SUPPLY -> #NAME?
A7: PIPE SIDE | B7: L | C7: =Left -> #NAME?
B8: R | C8: =Right -> #NAME?
A9: WATER CONDITION | B9: L | C9: =20/28 -> 0.71428571
B10: H | C10: =20/30 -> 0.66666667
A11: HUMIDIFICATION | B11: S | C11: = STEAM HUMIDIFIER 15kg/h
B12: 0 | C12: =NONE -> #NAME?
A13: ESP | B13: H | C13: = 100 Pa ESP
B14: L | C14: = 50 Pa ESP
B15: S | C15: =…. Pa ESP -> #NAME?
A16: DAMPER | B16: 1 | C16: =ON TOP -> #NAME?
B17: 0 | C17: =NONE -> #NAME?
A18: Temp Sensors | B18: S | C18: =RETURN and SUPPLY Avg Temp Sensor -> #NAME?
B19: O | C19: =RETURN and SUPPLY Temp/Hum -> #NAME?
A20: Leak Detaction | B20: S | C20: =Wire Type -> #NAME?
B21: O | C21: =Additional Leak Sensor -> #NAME?
A22: Valve Options | B22: N | C22: = Only 0-10V Cooling Demand output
B23: F | C23: = Flowmeter and 0-10V Output
B24: 2 | C24: = 2 Way Valve
B25: 3 | C25: = 3 Way Valve (Valve possitioned out of the unit at the pipe outlet, bypass line should be done by customer)
B26: E | C26: = 2 Way Valve w Energy Measurement
B27: P | C27: =Pressure Independent Control Valve -> #NAME?
A28: Corridor Control | B28: 0 | C28: =NONE -> #NAME?
B29: 1 | C29: =Corridors dP -> #NAME?
B30: 2 | C30: =Double dP -> #NAME?
B31: 3 | C31: = Corridors dP and Temperature Sensor***
B32: 4 | C32: = Corridors Double dP and Temperature Sensor***
B33: 5 | C33: =Temperature Sensor ***
A34: Power | B34: 0 | C34: = 400V /3P+N / 50hZ
B35: 1 | C35: = 400V / 3P+N / 60Hz
A36: Power Supply | B36: N | C36: =NONE -> #NAME?
B37: A
B38: B
B39: U | C39: =Single SUPPLY w UltraCap -> #NAME?
A40: Power Measurment | B40: 0 | C40: =Double SUPPLY w Ats -> #NAME?
...
